12-12-2023 10:49:48       root     INFO: 252 record(s) were imported successfully!!!
12-12-2023 11:32:52       root     INFO: 0 record(s) were imported successfully!!!
12-12-2023 12:16:39       root     INFO: 0 record(s) were imported successfully!!!
12-12-2023 12:19:41       root     INFO: 194 record(s) were imported successfully!!!
12-12-2023 13:04:40   __main__    ERROR: HTTP Status:400 - "error":"The following fields were not found in the project as real data fields: "
12-12-2023 13:21:51       root     INFO: 252 record(s) were imported successfully!!!
12-12-2023 13:27:15       root     INFO: 252 record(s) were imported successfully!!!
12-12-2023 13:32:30       root    ERROR: Exception Occurred. Expecting value: line 1 column 1 (char 0)
Traceback (most recent call last):
  File "/Users/berchie.agyemang.nti.admin/Developer/redcap.connector/src/importdata.py", line 27, in import_records
    import_record = json.load(jf)
                    ^^^^^^^^^^^^^
  File "/Users/berchie.agyemang.nti.admin/.pyenv/versions/3.11.6/lib/python3.11/json/__init__.py", line 293, in load
    return loads(fp.read(),
           ^^^^^^^^^^^^^^^^
  File "/Users/berchie.agyemang.nti.admin/.pyenv/versions/3.11.6/lib/python3.11/json/__init__.py", line 346, in loads
    return _default_decoder.decode(s)
           ^^^^^^^^^^^^^^^^^^^^^^^^^^
  File "/Users/berchie.agyemang.nti.admin/.pyenv/versions/3.11.6/lib/python3.11/json/decoder.py", line 337, in decode
    obj, end = self.raw_decode(s, idx=_w(s, 0).end())
               ^^^^^^^^^^^^^^^^^^^^^^^^^^^^^^^^^^^^^^
  File "/Users/berchie.agyemang.nti.admin/.pyenv/versions/3.11.6/lib/python3.11/json/decoder.py", line 355, in raw_decode
    raise JSONDecodeError("Expecting value", s, err.value) from None
json.decoder.JSONDecodeError: Expecting value: line 1 column 1 (char 0)
12-12-2023 13:43:07       root     INFO: 0 record(s) were imported successfully!!!
14-12-2023 12:21:33       root     INFO: 0 record(s) were imported successfully!!!
14-12-2023 12:27:48       root     INFO: 6 record(s) were imported successfully!!!
14-12-2023 12:43:02   __main__    ERROR: There's an error importing data. [Errno 2] No such file or directory: '../data/import_data.csv'
Traceback (most recent call last):
  File "/Users/berchie.agyemang.nti.admin/Developer/redcap.connector/src/importdata.py", line 36, in import_records
    with open('../data/import_data.csv') as csv_file:
         ^^^^^^^^^^^^^^^^^^^^^^^^^^^^^^^
FileNotFoundError: [Errno 2] No such file or directory: '../data/import_data.csv'
14-12-2023 12:43:33       root     INFO: 6 record(s) were imported successfully!!!
14-12-2023 13:13:43       root    ERROR: Exception Occurred. Expected object or value
Traceback (most recent call last):
  File "/Users/berchie.agyemang.nti.admin/Developer/redcap.connector/src/importdata.py", line 34, in import_records
    df_obj = pd.read_json(record, orient='records', precise_float=True)
             ^^^^^^^^^^^^^^^^^^^^^^^^^^^^^^^^^^^^^^^^^^^^^^^^^^^^^^^^^^
  File "/Users/berchie.agyemang.nti.admin/Developer/redcap.connector/.venv/lib/python3.11/site-packages/pandas/io/json/_json.py", line 804, in read_json
    return json_reader.read()
           ^^^^^^^^^^^^^^^^^^
  File "/Users/berchie.agyemang.nti.admin/Developer/redcap.connector/.venv/lib/python3.11/site-packages/pandas/io/json/_json.py", line 1014, in read
    obj = self._get_object_parser(self.data)
          ^^^^^^^^^^^^^^^^^^^^^^^^^^^^^^^^^^
  File "/Users/berchie.agyemang.nti.admin/Developer/redcap.connector/.venv/lib/python3.11/site-packages/pandas/io/json/_json.py", line 1040, in _get_object_parser
    obj = FrameParser(json, **kwargs).parse()
          ^^^^^^^^^^^^^^^^^^^^^^^^^^^^^^^^^^^
  File "/Users/berchie.agyemang.nti.admin/Developer/redcap.connector/.venv/lib/python3.11/site-packages/pandas/io/json/_json.py", line 1173, in parse
    self._parse()
  File "/Users/berchie.agyemang.nti.admin/Developer/redcap.connector/.venv/lib/python3.11/site-packages/pandas/io/json/_json.py", line 1393, in _parse
    ujson_loads(json, precise_float=self.precise_float), dtype=None
    ^^^^^^^^^^^^^^^^^^^^^^^^^^^^^^^^^^^^^^^^^^^^^^^^^^^
ValueError: Expected object or value
14-12-2023 13:14:49       root     INFO: 6 record(s) were imported successfully!!!
14-12-2023 13:45:35       root    ERROR: Exception Occurred. Expecting value: line 1 column 1 (char 0)
Traceback (most recent call last):
  File "/Users/berchie.agyemang.nti.admin/Developer/redcap.connector/src/importdata.py", line 28, in import_records
    import_record = json.load(jf)
                    ^^^^^^^^^^^^^
  File "/Users/berchie.agyemang.nti.admin/.pyenv/versions/3.11.6/lib/python3.11/json/__init__.py", line 293, in load
    return loads(fp.read(),
           ^^^^^^^^^^^^^^^^
  File "/Users/berchie.agyemang.nti.admin/.pyenv/versions/3.11.6/lib/python3.11/json/__init__.py", line 346, in loads
    return _default_decoder.decode(s)
           ^^^^^^^^^^^^^^^^^^^^^^^^^^
  File "/Users/berchie.agyemang.nti.admin/.pyenv/versions/3.11.6/lib/python3.11/json/decoder.py", line 337, in decode
    obj, end = self.raw_decode(s, idx=_w(s, 0).end())
               ^^^^^^^^^^^^^^^^^^^^^^^^^^^^^^^^^^^^^^
  File "/Users/berchie.agyemang.nti.admin/.pyenv/versions/3.11.6/lib/python3.11/json/decoder.py", line 355, in raw_decode
    raise JSONDecodeError("Expecting value", s, err.value) from None
json.decoder.JSONDecodeError: Expecting value: line 1 column 1 (char 0)
14-12-2023 13:47:41   __main__     INFO: No data to import.
14-12-2023 13:51:49       root     INFO: 6 record(s) were imported successfully!!!
20-12-2023 14:32:32   __main__    ERROR: Key Error Occurred. 'id'
Traceback (most recent call last):
  File "/Users/berchie.agyemang.nti.admin/Developer/redcap.connector/src/pull_data_senaite.py", line 173, in get_analyses_result
    analyses_data[redcap_variables["id"]] = client_sample_id.replace(client_sample_id[10:], 'T0--1')
                  ~~~~~~~~~~~~~~~~^^^^^^
KeyError: 'id'
20-12-2023 14:48:49   __main__    ERROR: Key Error Occurred. 'id'
Traceback (most recent call last):
  File "/Users/berchie.agyemang.nti.admin/Developer/redcap.connector/src/pull_data_senaite.py", line 221, in get_analyses_result
    analyses_data[redcap_variables["id"]] = client_sample_id.replace(client_sample_id[10:], 'T0--2')
                  ~~~~~~~~~~~~~~~~^^^^^^
KeyError: 'id'
20-12-2023 15:51:48   __main__    ERROR: There's an error importing data. [Errno 2] No such file or directory: '../data/import_data.csv'
Traceback (most recent call last):
  File "/Users/berchie.agyemang.nti.admin/Developer/redcap.connector/src/importdata.py", line 44, in import_records
    with open('../data/import_data.csv') as csv_file:
         ^^^^^^^^^^^^^^^^^^^^^^^^^^^^^^^
FileNotFoundError: [Errno 2] No such file or directory: '../data/import_data.csv'
20-12-2023 15:54:27       root     INFO: 14 record(s) were imported successfully!!!
20-12-2023 15:57:00       root     INFO: 1 record(s) were imported successfully!!!
20-12-2023 15:57:32       root     INFO: 1 record(s) were imported successfully!!!
20-12-2023 16:44:10       root     INFO: 9 record(s) were imported successfully!!!
21-12-2023 18:56:09       root     INFO: 9 of P21 record(s) were imported successfully!!!
21-12-2023 18:56:09   __main__    ERROR: There's an error importing data. [Errno 2] No such file or directory: '../data'
Traceback (most recent call last):
  File "/Users/berchie.agyemang.nti.admin/Developer/redcap.connector/src/importdata.py", line 137, in import_records
    to_csv_file()
  File "/Users/berchie.agyemang.nti.admin/Developer/redcap.connector/src/importdata.py", line 32, in to_csv_file
    for item in Path('../data/').iterdir():
  File "/Users/berchie.agyemang.nti.admin/.pyenv/versions/3.11.6/lib/python3.11/pathlib.py", line 931, in iterdir
    for name in os.listdir(self):
                ^^^^^^^^^^^^^^^^
FileNotFoundError: [Errno 2] No such file or directory: '../data'
22-12-2023 11:03:19       root     INFO: 9 of P21 record(s) were imported successfully!!!
28-12-2023 14:32:54       root     INFO: CHECK_STATUS: No csv file for either MBC T6-T12 or Fever visit lab results was found
28-12-2023 14:32:55       root     INFO: CHECK_STATUS: 9 of P21 record(s) were imported successfully!!!
28-12-2023 15:45:42       root     INFO: 9 of P21 record(s) were imported successfully!!!
04-01-2024 11:41:14   __main__     INFO: SENAITE: No records was found!
04-01-2024 11:55:45   __main__     INFO: SENAITE: No P21 lab records was found!
04-01-2024 11:57:45   __main__     INFO: SENAITE: No M19 lab records was found!
05-01-2024 14:18:47   __main__     INFO: No P21 data to import.
05-01-2024 14:29:41   __main__     INFO: SENAITE: No M19 lab records was found!
