01-03-2024 14:28:59       root     INFO: 6 of M19 record(s) were imported successfully!!!
01-03-2024 14:33:08       root     INFO: 6 of M19 record(s) were imported successfully!!!
01-03-2024 14:38:43       root     INFO: 6 of M19 record(s) were imported successfully!!!
04-03-2024 04:17:49       root    ERROR: Exception occurred
Traceback (most recent call last):
  File "/home/berchie/Developer/redcap-connector/redcap-connector/senaite_connect.py", line 24, in senaite_connect
    reqs = requests.post(env_config["BASE_URL"] + "/login", params={"__ac_name": env_config['SENAITE_USERNAME'],
                         ~~~~~~~~~~^^^^^^^^^^^^
KeyError: 'BASE_URL'
05-03-2024 00:49:29       root    ERROR: Exception occurred
Traceback (most recent call last):
  File "/home/berchie/Developer/redcap-connector/redcap-connector/senaite_connect.py", line 24, in senaite_connect
    reqs = requests.post(env_config["BASE_URL"] + "/login", params={"__ac_name": env_config['SENAITE_USERNAME'],
                         ~~~~~~~~~~^^^^^^^^^^^^
KeyError: 'BASE_URL'
05-03-2024 13:54:12       root    ERROR: Exception occurred
Traceback (most recent call last):
  File "/home/berchie/Developer/redcap-connector/redcap-connector/senaite_connect.py", line 24, in senaite_connect
    reqs = requests.post(env_config["BASE_URL"] + "/login", params={"__ac_name": env_config['SENAITE_USERNAME'],
                         ~~~~~~~~~~^^^^^^^^^^^^
KeyError: 'BASE_URL'
