01-03-2024 14:28:59       root     INFO: 6 of M19 record(s) were imported successfully!!!
01-03-2024 14:33:08       root     INFO: 6 of M19 record(s) were imported successfully!!!
01-03-2024 14:38:43       root     INFO: 6 of M19 record(s) were imported successfully!!!
04-03-2024 04:17:49       root    ERROR: Exception occurred
Traceback (most recent call last):
  File "/home/berchie/Developer/redcap-connector/redcap-connector/senaite_connect.py", line 24, in senaite_connect
    reqs = requests.post(env_config["BASE_URL"] + "/login", params={"__ac_name": env_config['SENAITE_USERNAME'],
                         ~~~~~~~~~~^^^^^^^^^^^^
KeyError: 'BASE_URL'
05-03-2024 00:49:29       root    ERROR: Exception occurred
Traceback (most recent call last):
  File "/home/berchie/Developer/redcap-connector/redcap-connector/senaite_connect.py", line 24, in senaite_connect
    reqs = requests.post(env_config["BASE_URL"] + "/login", params={"__ac_name": env_config['SENAITE_USERNAME'],
                         ~~~~~~~~~~^^^^^^^^^^^^
KeyError: 'BASE_URL'
05-03-2024 13:54:12       root    ERROR: Exception occurred
Traceback (most recent call last):
  File "/home/berchie/Developer/redcap-connector/redcap-connector/senaite_connect.py", line 24, in senaite_connect
    reqs = requests.post(env_config["BASE_URL"] + "/login", params={"__ac_name": env_config['SENAITE_USERNAME'],
                         ~~~~~~~~~~^^^^^^^^^^^^
KeyError: 'BASE_URL'
07-03-2024 02:52:22 redcapconnector.check_status     INFO: Error occurred: [Errno 2] No such file or directory: '/home/berchie/Developer/src/log/redcap_connector.log'
07-03-2024 02:55:35 redcapconnector.check_status     INFO: Error occurred: [Errno 2] No such file or directory: '/home/berchie/Developer/src/log/redcap_connector.log'
07-03-2024 02:59:45 redcapconnector.check_status     INFO: Error occurred: [Errno 2] No such file or directory: '/home/berchie/Developer/redcapconnector/data/daily_result'
07-03-2024 03:01:25 redcapconnector.check_status     INFO: Error occurred: [Errno 2] No such file or directory: '/home/berchie/Developer/redcapconnector/redcapconntor/data/daily_result'
07-03-2024 03:02:09 redcapconnector.check_status     INFO: Error occurred: [Errno 2] No such file or directory: '/home/berchie/Developer/redcapconnector/redcapconntor/data/daily_result'
07-03-2024 04:29:39       root    ERROR: Exception occurred
Traceback (most recent call last):
  File "/home/berchie/Developer/redcapconnector/redcapconnector/senaite_connect.py", line 24, in senaite_connect
    reqs = requests.post(env_config["BASE_URL"] + "/login", params={"__ac_name": env_config['SENAITE_USERNAME'],
                         ~~~~~~~~~~^^^^^^^^^^^^
KeyError: 'BASE_URL'
07-03-2024 04:34:24       root    ERROR: Exception occurred
Traceback (most recent call last):
  File "/home/berchie/Developer/redcapconnector/redcapconnector/senaite_connect.py", line 24, in senaite_connect
    reqs = requests.post(env_config["BASE_URL"] + "/login", params={"__ac_name": env_config['SENAITE_USERNAME'],
                         ~~~~~~~~~~^^^^^^^^^^^^
KeyError: 'BASE_URL'
